2024-02-29 17:21:27,038 INFO    StreamThr :78819 [internal.py:wandb_internal():86] W&B internal server running at pid: 78819, started at: 2024-02-29 17:21:27.037610
2024-02-29 17:21:27,040 DEBUG   HandlerThread:78819 [handler.py:handle_request():146] handle_request: status
2024-02-29 17:21:27,042 INFO    WriterThread:78819 [datastore.py:open_for_write():87] open: /home/rafael/Projects/ETH/FS2024/PLR_exercises/plr-exercise/wandb/run-20240229_172127-qc739bts/run-qc739bts.wandb
2024-02-29 17:21:27,043 DEBUG   SenderThread:78819 [sender.py:send():382] send: header
2024-02-29 17:21:27,050 DEBUG   SenderThread:78819 [sender.py:send():382] send: run
2024-02-29 17:21:30,503 INFO    SenderThread:78819 [retry.py:__call__():172] Retry attempt failed:
Traceback (most recent call last):
  File "/home/rafael/venv/plr_env/lib/python3.10/site-packages/urllib3/connection.py", line 198, in _new_conn
    sock = connection.create_connection(
  File "/home/rafael/venv/plr_env/lib/python3.10/site-packages/urllib3/util/connection.py", line 60, in create_connection
    for res in socket.getaddrinfo(host, port, family, socket.SOCK_STREAM):
  File "/usr/lib/python3.10/socket.py", line 955, in getaddrinfo
    for res in _socket.getaddrinfo(host, port, family, type, proto, flags):
socket.gaierror: [Errno -3] Temporary failure in name resolution

The above exception was the direct cause of the following exception:

Traceback (most recent call last):
  File "/home/rafael/venv/plr_env/lib/python3.10/site-packages/urllib3/connectionpool.py", line 793, in urlopen
    response = self._make_request(
  File "/home/rafael/venv/plr_env/lib/python3.10/site-packages/urllib3/connectionpool.py", line 491, in _make_request
    raise new_e
  File "/home/rafael/venv/plr_env/lib/python3.10/site-packages/urllib3/connectionpool.py", line 467, in _make_request
    self._validate_conn(conn)
  File "/home/rafael/venv/plr_env/lib/python3.10/site-packages/urllib3/connectionpool.py", line 1099, in _validate_conn
    conn.connect()
  File "/home/rafael/venv/plr_env/lib/python3.10/site-packages/urllib3/connection.py", line 616, in connect
    self.sock = sock = self._new_conn()
  File "/home/rafael/venv/plr_env/lib/python3.10/site-packages/urllib3/connection.py", line 205, in _new_conn
    raise NameResolutionError(self.host, self, e) from e
urllib3.exceptions.NameResolutionError: <urllib3.connection.HTTPSConnection object at 0x7ff4de79b250>: Failed to resolve 'api.wandb.ai' ([Errno -3] Temporary failure in name resolution)

The above exception was the direct cause of the following exception:

Traceback (most recent call last):
  File "/home/rafael/venv/plr_env/lib/python3.10/site-packages/requests/adapters.py", line 486, in send
    resp = conn.urlopen(
  File "/home/rafael/venv/plr_env/lib/python3.10/site-packages/urllib3/connectionpool.py", line 847, in urlopen
    retries = retries.increment(
  File "/home/rafael/venv/plr_env/lib/python3.10/site-packages/urllib3/util/retry.py", line 515, in increment
    raise MaxRetryError(_pool, url, reason) from reason  # type: ignore[arg-type]
urllib3.exceptions.MaxRetryError: HTTPSConnectionPool(host='api.wandb.ai', port=443): Max retries exceeded with url: /graphql (Caused by NameResolutionError("<urllib3.connection.HTTPSConnection object at 0x7ff4de79b250>: Failed to resolve 'api.wandb.ai' ([Errno -3] Temporary failure in name resolution)"))

During handling of the above exception, another exception occurred:

Traceback (most recent call last):
  File "/home/rafael/venv/plr_env/lib/python3.10/site-packages/wandb/sdk/lib/retry.py", line 131, in __call__
    result = self._call_fn(*args, **kwargs)
  File "/home/rafael/venv/plr_env/lib/python3.10/site-packages/wandb/sdk/internal/internal_api.py", line 369, in execute
    return self.client.execute(*args, **kwargs)  # type: ignore
  File "/home/rafael/venv/plr_env/lib/python3.10/site-packages/wandb/vendor/gql-0.2.0/wandb_gql/client.py", line 52, in execute
    result = self._get_result(document, *args, **kwargs)
  File "/home/rafael/venv/plr_env/lib/python3.10/site-packages/wandb/vendor/gql-0.2.0/wandb_gql/client.py", line 60, in _get_result
    return self.transport.execute(document, *args, **kwargs)
  File "/home/rafael/venv/plr_env/lib/python3.10/site-packages/wandb/sdk/lib/gql_request.py", line 58, in execute
    request = self.session.post(self.url, **post_args)
  File "/home/rafael/venv/plr_env/lib/python3.10/site-packages/requests/sessions.py", line 637, in post
    return self.request("POST", url, data=data, json=json, **kwargs)
  File "/home/rafael/venv/plr_env/lib/python3.10/site-packages/requests/sessions.py", line 589, in request
    resp = self.send(prep, **send_kwargs)
  File "/home/rafael/venv/plr_env/lib/python3.10/site-packages/requests/sessions.py", line 703, in send
    r = adapter.send(request, **kwargs)
  File "/home/rafael/venv/plr_env/lib/python3.10/site-packages/requests/adapters.py", line 519, in send
    raise ConnectionError(e, request=request)
requests.exceptions.ConnectionError: HTTPSConnectionPool(host='api.wandb.ai', port=443): Max retries exceeded with url: /graphql (Caused by NameResolutionError("<urllib3.connection.HTTPSConnection object at 0x7ff4de79b250>: Failed to resolve 'api.wandb.ai' ([Errno -3] Temporary failure in name resolution)"))
2024-02-29 17:21:32,051 DEBUG   HandlerThread:78819 [handler.py:handle_request():146] handle_request: keepalive
2024-02-29 17:21:33,096 DEBUG   HandlerThread:78819 [handler.py:handle_request():146] handle_request: shutdown
2024-02-29 17:21:33,097 INFO    HandlerThread:78819 [handler.py:finish():869] shutting down handler
2024-02-29 17:21:34,051 INFO    WriterThread:78819 [datastore.py:close():296] close: /home/rafael/Projects/ETH/FS2024/PLR_exercises/plr-exercise/wandb/run-20240229_172127-qc739bts/run-qc739bts.wandb
2024-02-29 17:56:15,602 INFO    SenderThread:78819 [dir_watcher.py:__init__():211] watching files in: /home/rafael/Projects/ETH/FS2024/PLR_exercises/plr-exercise/wandb/run-20240229_172127-qc739bts/files
2024-02-29 17:56:15,602 INFO    SenderThread:78819 [sender.py:_start_run_threads():1136] run started: qc739bts with start time 1709223687.039267
2024-02-29 17:56:15,602 INFO    SenderThread:78819 [sender.py:finish():1572] shutting down sender
2024-02-29 17:56:15,602 INFO    SenderThread:78819 [dir_watcher.py:finish():358] shutting down directory watcher
2024-02-29 17:56:16,605 INFO    SenderThread:78819 [dir_watcher.py:finish():388] scan: /home/rafael/Projects/ETH/FS2024/PLR_exercises/plr-exercise/wandb/run-20240229_172127-qc739bts/files
2024-02-29 17:56:16,605 INFO    SenderThread:78819 [dir_watcher.py:finish():402] scan save: /home/rafael/Projects/ETH/FS2024/PLR_exercises/plr-exercise/wandb/run-20240229_172127-qc739bts/files/config.yaml config.yaml
2024-02-29 17:56:16,605 INFO    SenderThread:78819 [file_pusher.py:finish():172] shutting down file pusher
2024-02-29 17:56:16,605 INFO    SenderThread:78819 [file_pusher.py:join():178] waiting for file pusher
2024-02-29 17:56:17,278 INFO    wandb-upload_0:78819 [upload_job.py:push():131] Uploaded file /home/rafael/Projects/ETH/FS2024/PLR_exercises/plr-exercise/wandb/run-20240229_172127-qc739bts/files/config.yaml
2024-02-29 17:56:17,607 INFO    SenderThread:78819 [file_stream.py:finish():595] file stream finish called
2024-02-29 17:56:17,892 INFO    SenderThread:78819 [file_stream.py:finish():599] file stream finish is done
